Workbook

Sheet IC Output - HUB
A2: CountryCode | B2: TeamId | C2: BUId | D2: Level | E2: Role | F2: ProductId | G2: ChannelId | H2: DataType | I2: PlanType | J2: EmployeeId | K2: WorkUnitId | L2: DataPeriod | M2: LevelOfMeasurement | N2: Sales | O2: Goals | P2: Attainment | Q2: Draw Multiplier | R2: Percent To Target | S2: Component Weight | T2: Target Pay | U2: New Hire Eligibilty | V2: Performance Eligibility | W2: IC Eligibility | X2: Pre Eligibilty Earnings | Y2: Previous Cycle Payout | Z2: Payout | AG2: Key for ZFIR
A3: GB | B3: GB_FF_AT1DM | C3: GEN MEDS | D3: Nation | E3: Sales Lead | F3: (Average Pre-Eligible Earnings of underlying team) x 1.5 | G3: Retail | H3: Dollar (£) | I3: Average of Underlying Terrs | J3: W90115334 | K3: GB_AT1DM | L3: Trimester | M3: Nation | Q3: 0.33333333 | S3: 1 | T3: 4877.57 | U3: 0 | V3: 1 | W3: 1 | X3: 929.41145 | Z3: 929.41145 | AG3: ='IC Output - HUB'!$N3&'IC Output - HUB'!$M3&'IC Output - HUB'!$I3&'IC Output - HUB'!$L3&'IC Output - HUB'!$P3 -> NationAverage of Underlying TerrsTrimester
A4: GB | B4: GB_FF_AT1DM | C4: GEN MEDS | D4: Territory | E4: Sales Rep | F4: Tzield | G4: Retail | H4: KPI | I4: MBO | J4: W50193707 | K4: GB_AT1DM_01 | L4: Trimester | M4: Territory | P4: 0 | Q4: 0.33333333 | S4: 0.4 | T4: 1951.03 | U4: 0 | V4: 1 | W4: 1 | X4: 0 | Z4: 0 | AG4: ='IC Output - HUB'!$N4&'IC Output - HUB'!$M4&'IC Output - HUB'!$I4&'IC Output - HUB'!$L4&'IC Output - HUB'!$P4 -> TerritoryMBOTrimester0
A5: GB | B5: GB_FF_AT1DM | C5: GEN MEDS | D5: Territory | E5: Sales Rep | F5: Tzield | G5: Retail | H5: KPI | I5: MBO | J5: W50193707 | K5: GB_AT1DM_01 | L5: Trimester | M5: Territory | P5: 0 | Q5: 0.33333333 | S5: 0.4 | T5: 1951.03 | U5: 0 | V5: 1 | W5: 1 | X5: 0 | Z5: 0 | AG5: ='IC Output - HUB'!$N5&'IC Output - HUB'!$M5&'IC Output - HUB'!$I5&'IC Output - HUB'!$L5&'IC Output - HUB'!$P5 -> TerritoryMBOTrimester0
A6: GB | B6: GB_FF_AT1DM | C6: GEN MEDS | D6: Territory | E6: Sales Rep | F6: Tzield | G6: Retail | H6: KPI | I6: MBO | J6: W50193707 | K6: GB_AT1DM_01 | L6: Trimester | M6: Territory | P6: 0 | Q6: 0.33333333 | S6: 0.2 | T6: 975.51 | U6: 0 | V6: 1 | W6: 1 | X6: 0 | Z6: 0 | AG6: ='IC Output - HUB'!$N6&'IC Output - HUB'!$M6&'IC Output - HUB'!$I6&'IC Output - HUB'!$L6&'IC Output - HUB'!$P6 -> TerritoryMBOTrimester0
A7: GB | B7: GB_FF_AT1DM | C7: GEN MEDS | D7: Territory | E7: Sales Rep | F7: Tzield | G7: Retail | H7: KPI | I7: MBO | J7: W00083744 | K7: GB_AT1DM_02 | L7: Trimester | M7: Territory | P7: 0 | Q7: 0.33333333 | S7: 0.4 | T7: 1951.03 | U7: 0 | V7: 1 | W7: 1 | X7: 0 | Z7: 0 | AG7: ='IC Output - HUB'!$N7&'IC Output - HUB'!$M7&'IC Output - HUB'!$I7&'IC Output - HUB'!$L7&'IC Output - HUB'!$P7 -> TerritoryMBOTrimester0
A8: GB | B8: GB_FF_AT1DM | C8: GEN MEDS | D8: Territory | E8: Sales Rep | F8: Tzield | G8: Retail | H8: KPI | I8: MBO | J8: W00083744 | K8: GB_AT1DM_02 | L8: Trimester | M8: Territory | P8: 0 | Q8: 0.33333333 | S8: 0.4 | T8: 1951.03 | U8: 0 | V8: 1 | W8: 1 | X8: 0 | Z8: 0 | AG8: ='IC Output - HUB'!$N8&'IC Output - HUB'!$M8&'IC Output - HUB'!$I8&'IC Output - HUB'!$L8&'IC Output - HUB'!$P8 -> TerritoryMBOTrimester0
A9: GB | B9: GB_FF_AT1DM | C9: GEN MEDS | D9: Territory | E9: Sales Rep | F9: Tzield | G9: Retail | H9: KPI | I9: MBO | J9: W00083744 | K9: GB_AT1DM_02 | L9: Trimester | M9: Territory | P9: 0 | Q9: 0.33333333 | S9: 0.2 | T9: 975.51 | U9: 0 | V9: 1 | W9: 1 | X9: 0 | Z9: 0 | AG9: ='IC Output - HUB'!$N9&'IC Output - HUB'!$M9&'IC Output - HUB'!$I9&'IC Output - HUB'!$L9&'IC Output - HUB'!$P9 -> TerritoryMBOTrimester0
A10: GB | B10: GB_FF_AT1DM | C10: GEN MEDS | D10: Territory | E10: Sales Rep | F10: Tzield | G10: Retail | H10: KPI | I10: MBO | J10: W50188951 | K10: GB_AT1DM_03 | L10: Trimester | M10: Territory | P10: 0 | Q10: 0.33333333 | S10: 0.4 | T10: 1951.03 | U10: 0 | V10: 1 | W10: 1 | X10: 0 | Z10: 0 | AG10: ='IC Output - HUB'!$N10&'IC Output - HUB'!$M10&'IC Output - HUB'!$I10&'IC Output - HUB'!$L10&'IC Output - HUB'!$P10 -> TerritoryMBOTrimester0
A11: GB | B11: GB_FF_AT1DM | C11: GEN MEDS | D11: Territory | E11: Sales Rep | F11: Tzield | G11: Retail | H11: KPI | I11: MBO | J11: W50188951 | K11: GB_AT1DM_03 | L11: Trimester | M11: Territory | P11: 0 | Q11: 0.33333333 | S11: 0.4 | T11: 1951.03 | U11: 0 | V11: 1 | W11: 1 | X11: 0 | Z11: 0 | AG11: ='IC Output - HUB'!$N11&'IC Output - HUB'!$M11&'IC Output - HUB'!$I11&'IC Output - HUB'!$L11&'IC Output - HUB'!$P11 -> TerritoryMBOTrimester0
A12: GB | B12: GB_FF_AT1DM | C12: GEN MEDS | D12: Territory | E12: Sales Rep | F12: Tzield | G12: Retail | H12: KPI | I12: MBO | J12: W50188951 | K12: GB_AT1DM_03 | L12: Trimester | M12: Territory | P12: 0 | Q12: 0.33333333 | S12: 0.2 | T12: 975.51 | U12: 0 | V12: 1 | W12: 1 | X12: 0 | Z12: 0 | AG12: ='IC Output - HUB'!$N12&'IC Output - HUB'!$M12&'IC Output - HUB'!$I12&'IC Output - HUB'!$L12&'IC Output - HUB'!$P12 -> TerritoryMBOTrimester0
A13: GB | B13: GB_FF_AT1DM | C13: GEN MEDS | D13: Territory | E13: Sales Rep | F13: Tzield | G13: Retail | H13: KPI | I13: MBO | J13: W50155217 | K13: GB_AT1DM_04 | L13: Trimester | M13: Territory | P13: 0 | Q13: 0.33333333 | S13: 0.4 | T13: 1951.03 | U13: 0 | V13: 1 | W13: 1 | X13: 0 | Z13: 0 | AG13: ='IC Output - HUB'!$N13&'IC Output - HUB'!$M13&'IC Output - HUB'!$I13&'IC Output - HUB'!$L13&'IC Output - HUB'!$P13 -> TerritoryMBOTrimester0
A14: GB | B14: GB_FF_AT1DM | C14: GEN MEDS | D14: Territory | E14: Sales Rep | F14: Tzield | G14: Retail | H14: KPI | I14: MBO | J14: W50155217 | K14: GB_AT1DM_04 | L14: Trimester | M14: Territory | P14: 0 | Q14: 0.33333333 | S14: 0.4 | T14: 1951.03 | U14: 0 | V14: 1 | W14: 1 | X14: 0 | Z14: 0 | AG14: ='IC Output - HUB'!$N14&'IC Output - HUB'!$M14&'IC Output - HUB'!$I14&'IC Output - HUB'!$L14&'IC Output - HUB'!$P14 -> TerritoryMBOTrimester0
A15: GB | B15: GB_FF_AT1DM | C15: GEN MEDS | D15: Territory | E15: Sales Rep | F15: Tzield | G15: Retail | H15: KPI | I15: MBO | J15: W50155217 | K15: GB_AT1DM_04 | L15: Trimester | M15: Territory | P15: 0 | Q15: 0.33333333 | S15: 0.2 | T15: 975.51 | U15: 0 | V15: 1 | W15: 1 | X15: 0 | Z15: 0 | AG15: ='IC Output - HUB'!$N15&'IC Output - HUB'!$M15&'IC Output - HUB'!$I15&'IC Output - HUB'!$L15&'IC Output - HUB'!$P15 -> TerritoryMBOTrimester0
... A18: GB | B18: GB_FF_AT1DM | C18: GEN MEDS | D18: Territory | E18: Sales Rep | F18: Tzield | G18: Retail | H18: KPI | I18: MBO | J18: W50153926 | K18: GB_AT1DM_05 | L18: Trimester | M18: Territory | P18: 0 | Q18: 0.33333333 | S18: 0.2 | T18: 975.51 | U18: 0 | V18: 1 | W18: 1 | X18: 0 | Z18: 0 | AG18: ='IC Output - HUB'!$N18&'IC Output - HUB'!$M18&'IC Output - HUB'!$I18&'IC Output - HUB'!$L18&'IC Output - HUB'!$P18 -> TerritoryMBOTrimester0
A19: GB | B19: GB_EP | C19: GEN MEDS | D19: Territory | E19: Sales Rep | F19: Toujeo | G19: Retail | H19: KPI | I19: MBO | J19: W50144502 | K19: GB_CMB2E | L19: Trimester | M19: Territory | Q19: 0.33333333 | S19: 0.2 | T19: 975.51 | U19: 0 | V19: 0 | W19: 0 | X19: 0 | Z19: 0 | AG19: ='IC Output - HUB'!$N19&'IC Output - HUB'!$M19&'IC Output - HUB'!$I19&'IC Output - HUB'!$L19&'IC Output - HUB'!$P19 -> TerritoryMBOTrimester
A20: GB | B20: GB_EP | C20: GEN MEDS | D20: Territory | E20: Sales Rep | F20: Praluent | G20: Retail | H20: Factored Units | I20: Goal Attainment | J20: W50144502 | K20: GB_CMB2E | L20: Trimester | M20: Nation | N20: 43553 | O20: 43056 | P20: 1.0115 | Q20: 0.33333333 | R20: 1.1006 | S20: 0.4 | T20: 1951.03 | U20: 0 | V20: 0 | W20: 0 | X20: 2147.3036 | Z20: 0 | AG20: ='IC Output - HUB'!$N20&'IC Output - HUB'!$M20&'IC Output - HUB'!$I20&'IC Output - HUB'!$L20&'IC Output - HUB'!$P20 -> 43553NationGoal AttainmentTrimester1.0115
A21: GB | B21: GB_EP | C21: GEN MEDS | D21: Territory | E21: Sales Rep | F21: Toujeo | G21: Retail | H21: Factored Units | I21: Goal Attainment | J21: W50144502 | K21: GB_CMB2E | L21: Trimester | M21: Nation | N21: 409698.17 | O21: 420041 | P21: 0.9754 | Q21: 0.33333333 | R21: 0.7582 | S21: 0.4 | T21: 1951.03 | U21: 0 | V21: 0 | W21: 0 | X21: 1479.2709 | Z21: 0 | AG21: ='IC Output - HUB'!$N21&'IC Output - HUB'!$M21&'IC Output - HUB'!$I21&'IC Output - HUB'!$L21&'IC Output - HUB'!$P21 -> 409698.171675NationGoal AttainmentTrimester0.9754
A22: GB | B22: GB_DEN_DES | C22: SPC | D22: Territory | E22: Sales Rep | F22: DUPIXENT | G22: Retail | H22: Units | I22: Goal Attainment | J22: W50023266 | K22: GB_DE_DEN1 | L22: Quarter | M22: Territory | N22: 3007 | O22: 3073.2331 | P22: 0.9784 | Q22: 0.25 | R22: 0.7872 | S22: 1 | T22: 3907.81 | U22: 0 | V22: 1 | W22: 1 | X22: 3076.228 | Z22: 3076.228 | AG22: ='IC Output - HUB'!$N22&'IC Output - HUB'!$M22&'IC Output - HUB'!$I22&'IC Output - HUB'!$L22&'IC Output - HUB'!$P22 -> 3007TerritoryGoal AttainmentQuarter0.9784
A23: GB | B23: GB_DEN_DES | C23: SPC | D23: Territory | E23: Sales Rep | F23: DUPIXENT | G23: Retail | H23: Units | I23: Goal Attainment | J23: W50023285 | K23: GB_DE_DEN2 | L23: Quarter | M23: Territory | N23: 3770 | O23: 3817.1602 | P23: 0.9876 | Q23: 0.25 | R23: 0.8773 | S23: 1 | T23: 3907.81 | U23: 0 | V23: 1 | W23: 1 | X23: 3428.3217 | Z23: 3428.3217 | AG23: ='IC Output - HUB'!$N23&'IC Output - HUB'!$M23&'IC Output - HUB'!$I23&'IC Output - HUB'!$L23&'IC Output - HUB'!$P23 -> 3770TerritoryGoal AttainmentQuarter0.9876
A24: GB | B24: GB_DEN_DES | C24: SPC | D24: Territory | E24: Sales Rep | F24: DUPIXENT | G24: Retail | H24: Units | I24: Goal Attainment | J24: W50023243 | K24: GB_DE_DEN3 | L24: Quarter | M24: Territory | N24: 3533 | O24: 3508.5139 | P24: 1.007 | Q24: 0.25 | R24: 1.0614 | S24: 1 | T24: 3907.81 | U24: 0 | V24: 1 | W24: 1 | X24: 4147.7495 | Z24: 4147.7495 | AG24: ='IC Output - HUB'!$N24&'IC Output - HUB'!$M24&'IC Output - HUB'!$I24&'IC Output - HUB'!$L24&'IC Output - HUB'!$P24 -> 3533TerritoryGoal AttainmentQuarter1.007
A25: GB | B25: GB_DEN_DES | C25: SPC | D25: Territory | E25: Sales Rep | F25: DUPIXENT | G25: Retail | H25: Units | I25: Goal Attainment | J25: W50145972 | K25: GB_DE_DEN4 | L25: Quarter | M25: Territory | N25: 2707 | O25: 2770.3338 | P25: 0.9771 | Q25: 0.25 | R25: 0.7746 | S25: 1 | T25: 3907.81 | U25: 0 | V25: 0 | W25: 0 | X25: 3026.9896 | Z25: 0 | AG25: ='IC Output - HUB'!$N25&'IC Output - HUB'!$M25&'IC Output - HUB'!$I25&'IC Output - HUB'!$L25&'IC Output - HUB'!$P25 -> 2707TerritoryGoal AttainmentQuarter0.9771
A26: GB | B26: GB_DEN_DES | C26: SPC | D26: Territory | E26: Sales Rep | F26: DUPIXENT | G26: Retail | H26: Units | I26: Goal Attainment | J26: W90076622 | K26: GB_DE_DEN6 | L26: Quarter | M26: Territory | N26: 1362 | O26: 1449.3211 | P26: 0.9398 | Q26: 0.25 | R26: 0.4414 | S26: 1 | T26: 3907.81 | U26: 0 | V26: 1 | W26: 1 | X26: 1724.9073 | Z26: 1724.9073 | AG26: ='IC Output - HUB'!$N26&'IC Output - HUB'!$M26&'IC Output - HUB'!$I26&'IC Output - HUB'!$L26&'IC Output - HUB'!$P26 -> 1362TerritoryGoal AttainmentQuarter0.9398
A27: GB | B27: GB_DEN_DES | C27: SPC | D27: Territory | E27: Sales Rep | F27: DUPIXENT | G27: Retail | H27: Units | I27: Goal Attainment | J27: W50023044 | K27: GB_DE_DES1 | L27: Quarter | M27: Territory | N27: 2637 | O27: 2748.4058 | P27: 0.9595 | Q27: 0.25 | R27: 0.6094 | S27: 1 | T27: 3907.81 | U27: 0 | V27: 1 | W27: 1 | X27: 2381.4194 | Z27: 2381.4194 | AG27: ='IC Output - HUB'!$N27&'IC Output - HUB'!$M27&'IC Output - HUB'!$I27&'IC Output - HUB'!$L27&'IC Output - HUB'!$P27 -> 2637TerritoryGoal AttainmentQuarter0.9595
A28: GB | B28: GB_DEN_DES | C28: SPC | D28: Territory | E28: Sales Rep | F28: DUPIXENT | G28: Retail | H28: Units | I28: Goal Attainment | J28: W50054088 | K28: GB_DE_DES2 | L28: Quarter | M28: Territory | N28: 1603 | O28: 1564.7253 | P28: 1.0245 | Q28: 0.25 | R28: 1.2121 | S28: 1 | T28: 3907.81 | U28: 0 | V28: 1 | W28: 1 | X28: 4736.6565 | Z28: 4736.6565 | AG28: ='IC Output - HUB'!$N28&'IC Output - HUB'!$M28&'IC Output - HUB'!$I28&'IC Output - HUB'!$L28&'IC Output - HUB'!$P28 -> 1603TerritoryGoal AttainmentQuarter1.0245
A29: GB | B29: GB_DEN_DES | C29: SPC | D29: Territory | E29: Sales Rep | F29: DUPIXENT | G29: Retail | H29: Units | I29: Goal Attainment | J29: W50138008 | K29: GB_DE_DES3 | L29: Quarter | M29: Territory | N29: 1683 | O29: 1664.6743 | P29: 1.011 | Q29: 0.25 | R29: 1.0962 | S29: 1 | T29: 3907.81 | U29: 0 | V29: 1 | W29: 1 | X29: 4283.7413 | Z29: 4283.7413 | AG29: ='IC Output - HUB'!$N29&'IC Output - HUB'!$M29&'IC Output - HUB'!$I29&'IC Output - HUB'!$L29&'IC Output - HUB'!$P29 -> 1683TerritoryGoal AttainmentQuarter1.011
A30: GB | B30: GB_DEN_DES | C30: SPC | D30: Territory | E30: Sales Rep | F30: DUPIXENT | G30: Retail | H30: Units | I30: Goal Attainment | J30: W90093092 | K30: GB_DE_DES4 | L30: Quarter | M30: Territory | N30: 3332 | O30: 3155.0008 | P30: 1.0561 | Q30: 0.25 | R30: 1.4693 | S30: 1 | T30: 3907.81 | U30: 0 | V30: 1 | W30: 1 | X30: 5741.7452 | Z30: 5741.7452 | AG30: ='IC Output - HUB'!$N30&'IC Output - HUB'!$M30&'IC Output - HUB'!$I30&'IC Output - HUB'!$L30&'IC Output - HUB'!$P30 -> 3332TerritoryGoal AttainmentQuarter1.0561
A31: GB | B31: GB_DEN_DES | C31: SPC | D31: Territory | E31: Sales Rep | F31: DUPIXENT | G31: Retail | H31: Units | I31: Goal Attainment | J31: W50155370 | K31: GB_DE_DES6 | L31: Quarter | M31: Territory | N31: 3356 | O31: 3331.8426 | P31: 1.0073 | Q31: 0.25 | R31: 1.064 | S31: 1 | T31: 3907.81 | U31: 0 | V31: 1 | W31: 1 | X31: 4157.9098 | Z31: 4157.9098 | AG31: ='IC Output - HUB'!$N31&'IC Output - HUB'!$M31&'IC Output - HUB'!$I31&'IC Output - HUB'!$L31&'IC Output - HUB'!$P31 -> 3356TerritoryGoal AttainmentQuarter1.0073
... A33: GB | B33: GB_DEN_DES | C33: SPC | D33: Territory | E33: Sales Rep | F33: DUPIXENT | G33: Retail | H33: Units | I33: Goal Attainment | J33: W50083205 | K33: GB_DE_DES7 | L33: Quarter | M33: Territory | N33: 1745 | O33: 1834.974 | P33: 0.951 | Q33: 0.25 | R33: 0.5343 | S33: 1 | T33: 3907.81 | U33: 0 | V33: 1 | W33: 1 | X33: 2087.9429 | Z33: 2087.9429 | AG33: ='IC Output - HUB'!$N33&'IC Output - HUB'!$M33&'IC Output - HUB'!$I33&'IC Output - HUB'!$L33&'IC Output - HUB'!$P33 -> 1745TerritoryGoal AttainmentQuarter0.951
A34: GB | B34: GB_DEN_DES | C34: SPC | D34: Region | E34: Sales Lead | F34: (Average Pre-Eligible Earnings of underlying team) x 1.5 | G34: Retail | H34: Dollar (£) | I34: Average of Underlying Terrs | J34: W90006551 | K34: GB_DE_RSM_NORTH | L34: Quarter | M34: Region | Q34: 0.25 | S34: 1 | T34: 3907.81 | U34: 0 | V34: 1 | W34: 1 | X34: 4621.2589 | Z34: 4621.2589 | AG34: ='IC Output - HUB'!$N34&'IC Output - HUB'!$M34&'IC Output - HUB'!$I34&'IC Output - HUB'!$L34&'IC Output - HUB'!$P34 -> RegionAverage of Underlying TerrsQuarter
A35: GB | B35: GB_DEN_DES | C35: SPC | D35: Region | E35: Sales Lead | F35: (Average Pre-Eligible Earnings of underlying team) x 1.5 | G35: Retail | H35: Dollar (£) | I35: Average of Underlying Terrs | J35: W50161003 | K35: GB_DE_RSM_SOUTH | L35: Quarter | M35: Region | Q35: 0.25 | S35: 1 | T35: 3907.81 | U35: 0 | V35: 1 | W35: 1 | X35: 5847.3538 | Z35: 5847.3538 | AG35: ='IC Output - HUB'!$N35&'IC Output - HUB'!$M35&'IC Output - HUB'!$I35&'IC Output - HUB'!$L35&'IC Output - HUB'!$P35 -> RegionAverage of Underlying TerrsQuarter
A36: GB | B36: GB_EP | C36: GEN MEDS | D36: Nation | E36: Sales Lead | F36: (Average Pre-Eligible Earnings of underlying team) x 1.5 | G36: Retail | H36: Pounds | I36: Average of Underlying Terrs | J36: W50140140 | K36: GB_EP_M | L36: Trimester | M36: Nation | Q36: 0.33333333 | S36: 1 | T36: 4877.57 | U36: 0 | V36: 1 | W36: 1 | X36: 5439.8618 | Z36: 5439.8618 | AG36: ='IC Output - HUB'!$N36&'IC Output - HUB'!$M36&'IC Output - HUB'!$I36&'IC Output - HUB'!$L36&'IC Output - HUB'!$P36 -> NationAverage of Underlying TerrsTrimester
A37: GB | B37: GB_EP | C37: GEN MEDS | D37: Territory | E37: Sales Rep | F37: Toujeo | G37: Retail | H37: KPI | I37: MBO | J37: W90120341 | K37: GB_EP01 | L37: Trimester | M37: Territory | P37: 0 | Q37: 0.33333333 | R37: 0 | S37: 0.2 | T37: 975.51 | U37: 0 | V37: 1 | W37: 1 | X37: 0 | Z37: 0 | AG37: ='IC Output - HUB'!$N37&'IC Output - HUB'!$M37&'IC Output - HUB'!$I37&'IC Output - HUB'!$L37&'IC Output - HUB'!$P37 -> TerritoryMBOTrimester0
A38: GB | B38: GB_EP | C38: GEN MEDS | D38: Territory | E38: Sales Rep | F38: Praluent | G38: Retail | H38: Factored Units | I38: Goal Attainment | J38: W90120341 | K38: GB_EP01 | L38: Trimester | M38: Nation | N38: 43553 | O38: 43056 | P38: 1.0115 | Q38: 0.33333333 | R38: 1.1006 | S38: 0.4 | T38: 1951.03 | U38: 0 | V38: 1 | W38: 1 | X38: 2147.3036 | Z38: 2147.3036 | AG38: ='IC Output - HUB'!$N38&'IC Output - HUB'!$M38&'IC Output - HUB'!$I38&'IC Output - HUB'!$L38&'IC Output - HUB'!$P38 -> 43553NationGoal AttainmentTrimester1.0115
A39: GB | B39: GB_EP | C39: GEN MEDS | D39: Territory | E39: Sales Rep | F39: Toujeo | G39: Retail | H39: Factored Units | I39: Goal Attainment | J39: W90120341 | K39: GB_EP01 | L39: Trimester | M39: Nation | N39: 409698.17 | O39: 420041 | P39: 0.9754 | Q39: 0.33333333 | R39: 0.7582 | S39: 0.4 | T39: 1951.03 | U39: 0 | V39: 1 | W39: 1 | X39: 1479.2709 | Z39: 1479.2709 | AG39: ='IC Output - HUB'!$N39&'IC Output - HUB'!$M39&'IC Output - HUB'!$I39&'IC Output - HUB'!$L39&'IC Output - HUB'!$P39 -> 409698.171675NationGoal AttainmentTrimester0.9754
A40: GB | B40: GB_EP | C40: GEN MEDS | D40: Territory | E40: Sales Rep | F40: Toujeo | G40: Retail | H40: KPI | I40: MBO | J40: W00080507 | K40: GB_EP02 | L40: Trimester | M40: Territory | P40: 0 | Q40: 0.33333333 | R40: 0 | S40: 0.2 | T40: 975.51 | U40: 0 | V40: 1 | W40: 1 | X40: 0 | Z40: 0 | AG40: ='IC Output - HUB'!$N40&'IC Output - HUB'!$M40&'IC Output - HUB'!$I40&'IC Output - HUB'!$L40&'IC Output - HUB'!$P40 -> TerritoryMBOTrimester0
A41: GB | B41: GB_EP | C41: GEN MEDS | D41: Territory | E41: Sales Rep | F41: Praluent | G41: Retail | H41: Factored Units | I41: Goal Attainment | J41: W00080507 | K41: GB_EP02 | L41: Trimester | M41: Nation | N41: 43553 | O41: 43056 | P41: 1.0115 | Q41: 0.33333333 | R41: 1.1006 | S41: 0.4 | T41: 1951.03 | U41: 0 | V41: 1 | W41: 1 | X41: 2147.3036 | Z41: 2147.3036 | AG41: ='IC Output - HUB'!$N41&'IC Output - HUB'!$M41&'IC Output - HUB'!$I41&'IC Output - HUB'!$L41&'IC Output - HUB'!$P41 -> 43553NationGoal AttainmentTrimester1.0115
A42: GB | B42: GB_EP | C42: GEN MEDS | D42: Territory | E42: Sales Rep | F42: Toujeo | G42: Retail | H42: Factored Units | I42: Goal Attainment | J42: W00080507 | K42: GB_EP02 | L42: Trimester | M42: Nation | N42: 409698.17 | O42: 420041 | P42: 0.9754 | Q42: 0.33333333 | R42: 0.7582 | S42: 0.4 | T42: 1951.03 | U42: 0 | V42: 1 | W42: 1 | X42: 1479.2709 | Z42: 1479.2709 | AG42: ='IC Output - HUB'!$N42&'IC Output - HUB'!$M42&'IC Output - HUB'!$I42&'IC Output - HUB'!$L42&'IC Output - HUB'!$P42 -> 409698.171675NationGoal AttainmentTrimester0.9754
A43: GB | B43: GB_EP | C43: GEN MEDS | D43: Territory | E43: Sales Rep | F43: Toujeo | G43: Retail | H43: KPI | I43: MBO | J43: W50140145 | K43: GB_EP03 | L43: Trimester | M43: Territory | P43: 0 | Q43: 0.33333333 | R43: 0 | S43: 0.2 | T43: 975.51 | U43: 0 | V43: 1 | W43: 1 | X43: 0 | Z43: 0 | AG43: ='IC Output - HUB'!$N43&'IC Output - HUB'!$M43&'IC Output - HUB'!$I43&'IC Output - HUB'!$L43&'IC Output - HUB'!$P43 -> TerritoryMBOTrimester0
A44: GB | B44: GB_EP | C44: GEN MEDS | D44: Territory | E44: Sales Rep | F44: Praluent | G44: Retail | H44: Factored Units | I44: Goal Attainment | J44: W50140145 | K44: GB_EP03 | L44: Trimester | M44: Nation | N44: 43553 | O44: 43056 | P44: 1.0115 | Q44: 0.33333333 | R44: 1.1006 | S44: 0.4 | T44: 1951.03 | U44: 0 | V44: 1 | W44: 1 | X44: 2147.3036 | Z44: 2147.3036 | AG44: ='IC Output - HUB'!$N44&'IC Output - HUB'!$M44&'IC Output - HUB'!$I44&'IC Output - HUB'!$L44&'IC Output - HUB'!$P44 -> 43553NationGoal AttainmentTrimester1.0115
...
